Workbook
Name _: EZJ!$X$91
Name Company_Name: EZJ!$E$7
Name Cost_of_Debt: WACC!$F$8
Name Cost_of_Preferred: WACC!$F$9
Name Diluted_Shares: DCF!$E$15
Name Discount_Rate: DCF!$E$17
Name Equity_Risk_Premium: WACC!$F$7
Name Hist_Year: DCF!$K$7
Name Max_Debt_EBITDAR: EZJ!$E$13
Name Max_Debt_Total_Cap: EZJ!$E$18
Name Next_Year: DCF!$K$8
Name Pct_Debt_Funding: EZJ!$E$10
Name Pub_Comps_Data: Public_Comps!$B$8:$AA$23
Name Pub_Comps_Info_Range: Public_Comps!$B$8:$AA$8
Name Risk_Free_Rate: WACC!$F$6
Name Scenario: DCF!$E$8
Name Share_Price: DCF!$E$14
Name Stub_Period: DCF!$E$12
Name Tax_Rate: EZJ!$N$61
Name Ticker: EZJ!$E$8
Name Ticker_Range: Public_Comps!$C$8:$C$23
Name Units: EZJ!$E$9
Name Val_Date: DCF!$E$11
Name Valuation_Date: DCF!$K$10

Sheet EZJ
B2: =Company_Name&" - Operating Model and Credit Analysis" -> easyJet plc - Operating Model and Credit Analysis
B3: (£ GBP in Millions Except for Per Share and Per Unit Data)
B5: Model Assumptions: | D5: Units:
C7: Company Name: | D7: Name | E7: easyJet plc | K7: Bond Price = 96.39 as per BBG
C8: Ticker: | D8: Name | E8: LSE:EZJ | K8: YTM = 3.074
C9: Conversion Units: | D9: # | E9: 100
C10: Debt Funding Percentage: | D10: % | E10: 1
C11: Operating Scenario: | D11: Name | E11: (See DCF tab to select)
C13: Maximum (Total Debt + Lease Liabilities) / EBITDAR: | D13: x | E13: =INDEX(E14:E16,MATCH(Scenario,$C14:$C16,0),1) -> 0
C14: =$C$31 -> Base | D14: x
C15: =$C$32 -> Downside | D15: x | E15: 6
C16: =$C$33 -> XT Downside | D16: x | E16: 7
C18: Maximum (Total Debt + Lease Liabilities) / Total Capital: | D18: % | E18: =INDEX(E19:E21,MATCH(Scenario,$C19:$C21,0),1) -> 0
C19: =$C$31 -> Base | D19: %
C20: =$C$32 -> Downside | D20: % | E20: 0.6
C21: =$C$33 -> XT Downside | D21: % | E21: 0.7
C23: Fiscal Year: | D23: Year | E23: =YEAR(E26) -> 2019 | F23: =YEAR(F26) -> 2019 | G23: =YEAR(G26) -> 2020 | H23: =YEAR(H26) -> 2020 | I23: =YEAR(I26) -> 2021 | J23: =YEAR(J26) -> 2021 | K23: =YEAR(K26) -> 2022 | L23: =YEAR(L26) -> 2022 | ... R23: =YEAR(R26) -> 2026 | T23: =YEAR(T26) -> 2019 | U23: =YEAR(U26) -> 2020 | V23: =YEAR(V26) -> 2021 | W23: =YEAR(W26) -> 2022 | X23: =YEAR(X26) -> 2023 | Y23: =YEAR(Y26) -> 2024 | Z23: =YEAR(Z26) -> 2025 | AA23: =YEAR(AA26) -> 2026
E25: =$E$25 -> Historical (Half-Years): | Q25: Projected (Annual): | T25: Historical: | Z25: =$Q$25 -> Projected (Annual):
B26: Financial Statement Assumptions: | D26: =$D$5 -> Units: | E26: 43555 | F26: =EOMONTH(E26,6) -> 43738 | G26: =EOMONTH(F26,6) -> 43921 | H26: =EOMONTH(G26,6) -> 44104 | I26: =EOMONTH(H26,6) -> 44286 | J26: =EOMONTH(I26,6) -> 44469 | K26: =EOMONTH(J26,6) -> 44651 | L26: =EOMONTH(K26,6) -> 44834 | M26: =EOMONTH(L26,6) -> 45016 | ... P26: =EOMONTH(O26,6) -> 45565 | Q26: =EOMONTH(P26,12) -> 45930 | R26: =EOMONTH(Q26,12) -> 46295 | T26: =F26 -> 43738 | U26: =EOMONTH(T26,12) -> 44104 | V26: =EOMONTH(U26,12) -> 44469 | W26: =EOMONTH(V26,12) -> 44834 | X26: =EOMONTH(W26,12) -> 45199 | Y26: =EOMONTH(X26,12) -> 45565 | Z26: =EOMONTH(Y26,12) -> 45930 | AA26: =EOMONTH(Z26,12) -> 46295
B27: Revenue Drivers:
C29: Available Seat Kilometres (ASK): | D29: Millions KM | E29: 49367 | F29: 66689 | G29: 46753 | H29: 16077 | I29: 8088 | J29: =33348-I29 -> 25260 | K29: 34287 | L29: =J29*(1+L30) -> 47994 | M29: =K29*(1+M30) -> 48001.8 | N29: =L29*(1+N30) -> 67191.6 | O29: =M29*(1+O30) -> 57602.16 | P29: =N29*(1+P30) -> 77270.34 | Q29: =SUM(O29:P29)*(1+Q30) -> 155103.37 | R29: =Q29*(1+R30) -> 174491.3 | T29: =SUMIF($E$23:$R$23,T$23,$E29:$R29) -> 116056 | U29: =SUMIF($E$23:$R$23,U$23,$E29:$R29) -> 62830 | V29: =SUMIF($E$23:$R$23,V$23,$E29:$R29) -> 33348 | W29: =SUMIF($E$23:$R$23,W$23,$E29:$R29) -> 82281 | X29: =SUMIF($E$23:$R$23,X$23,$E29:$R29) -> 115193.4 | Y29: =SUMIF($E$23:$R$23,Y$23,$E29:$R29) -> 134872.5 | Z29: =SUMIF($E$23:$R$23,Z$23,$E29:$R29) -> 155103.37 | AA29: =SUMIF($E$23:$R$23,AA$23,$E29:$R29) -> 174491.3
C30: Selected YoY Growth Rate: | D30: % | G30: =G29/E29-1 -> -0.052950351 | H30: =H29/F29-1 -> -0.75892576 | I30: =I29/G29-1 -> -0.82700575 | J30: =J29/H29-1 -> 0.57118865 | K30: =K29/I29-1 -> 3.2392433 | L30: =INDEX(L31:L33,MATCH(Scenario,$C31:$C33,0),1) -> 0.9 | M30: =INDEX(M31:M33,MATCH(Scenario,$C31:$C33,0),1) -> 0.4 | N30: =INDEX(N31:N33,MATCH(Scenario,$C31:$C33,0),1) -> 0.4 | O30: =INDEX(O31:O33,MATCH(Scenario,$C31:$C33,0),1) -> 0.2 | P30: =INDEX(P31:P33,MATCH(Scenario,$C31:$C33,0),1) -> 0.15 | Q30: =INDEX(Q31:Q33,MATCH(Scenario,$C31:$C33,0),1) -> 0.15 | R30: =INDEX(R31:R33,MATCH(Scenario,$C31:$C33,0),1) -> 0.125 | U30: =U29/T29-1 -> -0.45862342 | V30: =V29/U29-1 -> -0.46923444 | W30: =W29/V29-1 -> 1.4673444 | X30: =X29/W29-1 -> 0.4 | Y30: =Y29/X29-1 -> 0.17083531 | Z30: =Z29/Y29-1 -> 0.15 | AA30: =AA29/Z29-1 -> 0.125
C31: Base | D31: % | L31: 0.9 | M31: 0.4 | N31: 0.4 | O31: 0.2 | P31: 0.15 | Q31: 0.15 | R31: 0.125
C32: Downside | D32: % | L32: 0.4 | M32: 0.35 | N32: 0.3 | O32: 0.25 | P32: 0.25 | Q32: 0.175 | R32: 0.125
C33: XT Downside | D33: % | L33: 0.3 | M33: 0.3 | N33: 0.25 | O33: 0.2 | P33: 0.15 | Q33: 0.125 | R33: 0.1
C35: Selected Load Factor: | D35: % | E35: =E40/E29 -> 0.91338343 | F35: =F40/F29 -> 0.93943529 | G35: =G40/G29 -> 0.91801596 | H35: =H40/H29 -> 0.99483735 | I35: =I40/I29 -> 0.63501484 | J35: =J40/J29 -> 0.73072051 | K35: =K40/K29 -> 0.78195818 | L35: =INDEX(L36:L38,MATCH(Scenario,$C36:$C38,0),1) -> 0.85 | M35: =INDEX(M36:M38,MATCH(Scenario,$C36:$C38,0),1) -> 0.87 | N35: =INDEX(N36:N38,MATCH(Scenario,$C36:$C38,0),1) -> 0.9 | O35: =INDEX(O36:O38,MATCH(Scenario,$C36:$C38,0),1) -> 0.91 | P35: =INDEX(P36:P38,MATCH(Scenario,$C36:$C38,0),1) -> 0.92 | Q35: =INDEX(Q36:Q38,MATCH(Scenario,$C36:$C38,0),1) -> 0.925 | R35: =INDEX(R36:R38,MATCH(Scenario,$C36:$C38,0),1) -> 0.925 | T35: =T40/T29 -> 0.92835355 | U35: =U40/U29 -> 0.93767309 | V35: =V40/V29 -> 0.7075087 | W35: =W40/W29 -> 0.82164655 | X35: =X40/X29 -> 0.88749882 | Y35: =Y40/Y29 -> 0.91572914 | Z35: =Z40/Z29 -> 0.925 | AA35: =AA40/AA29 -> 0.925
C36: =$C$31 -> Base | D36: % | L36: 0.85 | M36: 0.87 | N36: 0.9 | O36: 0.91 | P36: 0.92 | Q36: 0.925 | R36: 0.925
C37: =$C$32 -> Downside | D37: % | L37: 0.85 | M37: 0.86 | N37: 0.88 | O37: 0.9 | P37: 0.91 | Q37: 0.92 | R37: 0.92
C38: =$C$33 -> XT Downside | D38: % | L38: 0.85 | M38: 0.855 | N38: 0.87 | O38: 0.88 | P38: 0.89 | Q38: 0.9 | R38: 0.91
C40: Revenue Passenger Kilometres (RPK): | D40: Millions KM | E40: 45091 | F40: 62650 | G40: 42920 | H40: 15994 | I40: 5136 | J40: =23594-I40 -> 18458 | K40: 26811 | L40: =L29*L35 -> 40794.9 | M40: =M29*M35 -> 41761.566 | N40: =N29*N35 -> 60472.44 | O40: =O29*O35 -> 52417.966 | P40: =P29*P35 -> 71088.713 | Q40: =Q29*Q35 -> 143470.62 | R40: =R29*R35 -> 161404.45 | T40: =SUMIF($E$23:$R$23,T$23,$E40:$R40) -> 107741 | U40: =SUMIF($E$23:$R$23,U$23,$E40:$R40) -> 58914 | V40: =SUMIF($E$23:$R$23,V$23,$E40:$R40) -> 23594 | W40: =SUMIF($E$23:$R$23,W$23,$E40:$R40) -> 67605.9 | X40: =SUMIF($E$23:$R$23,X$23,$E40:$R40) -> 102234.01 | Y40: =SUMIF($E$23:$R$23,Y$23,$E40:$R40) -> 123506.68 | Z40: =SUMIF($E$23:$R$23,Z$23,$E40:$R40) -> 143470.62 | AA40: =SUMIF($E$23:$R$23,AA$23,$E40:$R40) -> 161404.45
C41: YoY Growth Rate: | D41: % | G41: =G40/E40-1 -> -0.04814708 | H41: =H40/F40-1 -> -0.7447087 | I41: =I40/G40-1 -> -0.88033551 | J41: =J40/H40-1 -> 0.15405777 | K41: =K40/I40-1 -> 4.2202103 | L41: =L40/J40-1 -> 1.2101474 | M41: =M40/K40-1 -> 0.55762806 | N41: =N40/L40-1 -> 0.48235294 | ... P41: =P40/N40-1 -> 0.17555556 | Q41: =Q40/SUM(O40:P40)-1 -> 0.16164262 | R41: =R40/Q40-1 -> 0.125 | U41: =U40/T40-1 -> -0.45318867 | V41: =V40/U40-1 -> -0.59951794 | W41: =W40/V40-1 -> 1.8653853 | X41: =X40/W40-1 -> 0.51220538 | Y41: =Y40/X40-1 -> 0.20807824 | Z41: =Z40/Y40-1 -> 0.16164262 | AA41: =AA40/Z40-1 -> 0.125
C43: Passenger Revenue: | D43: £ M | E43: 1824 | F43: 3185 | G43: 1833 | H43: 470 | I43: 170 | J43: =1000-I43 -> 830 | K43: 985 | L43: =L40*L44/Units -> 1937.7577 | M43: =M40*M44/Units -> 1628.7011 | N43: =N40*N44/Units -> 2993.3858 | O43: =O40*O44/Units -> 2122.9276 | P43: =P40*P44/Units -> 3625.5244 | Q43: =Q40*Q44/Units -> 6671.3839 | R43: =R40*R44/Units -> 7666.7114 | T43: =SUMIF($E$23:$R$23,T$23,$E43:$R43) -> 5009 | U43: =SUMIF($E$23:$R$23,U$23,$E43:$R43) -> 2303 | V43: =SUMIF($E$23:$R$23,V$23,$E43:$R43) -> 1000 | W43: =SUMIF($E$23:$R$23,W$23,$E43:$R43) -> 2922.7577 | X43: =SUMIF($E$23:$R$23,X$23,$E43:$R43) -> 4622.0869 | Y43: =SUMIF($E$23:$R$23,Y$23,$E43:$R43) -> 5748.452 | Z43: =SUMIF($E$23:$R$23,Z$23,$E43:$R43) -> 6671.3839 | AA43: =SUMIF($E$23:$R$23,AA$23,$E43:$R43) -> 7666.7114
C44: Yield (Revenue per RPK): | D44: p / KM | E44: =E43/E$40*Units -> 4.0451531 | F44: =F43/F$40*Units -> 5.0837989 | G44: =G43/G$40*Units -> 4.2707363 | H44: =H43/H$40*Units -> 2.938602 | I44: =I43/I$40*Units -> 3.3099688 | J44: =J43/J$40*Units -> 4.4966952 | K44: =K43/K$40*Units -> 3.6738652 | L44: 4.75 | M44: 3.9 | N44: 4.95 | O44: 4.05 | P44: 5.1 | Q44: 4.65 | R44: 4.75 | T44: =T43/T$40*Units -> 4.6491122 | U44: =U43/U$40*Units -> 3.9090878 | V44: =V43/V$40*Units -> 4.2383657 | W44: =W43/W$40*Units -> 4.3232288 | X44: =X43/X$40*Units -> 4.5210855 | Y44: =Y43/Y$40*Units -> 4.6543653 | Z44: =Z43/Z$40*Units -> 4.65 | AA44: =AA43/AA$40*Units -> 4.75
C46: Ancillary Revenue: | D46: £ M | E46: 519 | F46: 857 | G46: 549 | H46: 157 | I46: 70 | J46: =458-I46 -> 388 | K46: 513 | L46: =L47*L40/Units -> 713.91075 | M46: =M47*M40/Units -> 647.30427 | N46: =N47*N40/Units -> 816.37794 | O46: =O47*O40/Units -> 602.8066 | P46: =P47*P40/Units -> 995.24198 | Q46: =Q47*Q40/Units -> 1865.1181 | R46: =R47*R40/Units -> 2178.9601 | T46: =SUMIF($E$23:$R$23,T$23,$E46:$R46) -> 1376 | U46: =SUMIF($E$23:$R$23,U$23,$E46:$R46) -> 706 | V46: =SUMIF($E$23:$R$23,V$23,$E46:$R46) -> 458 | W46: =SUMIF($E$23:$R$23,W$23,$E46:$R46) -> 1226.9108 | X46: =SUMIF($E$23:$R$23,X$23,$E46:$R46) -> 1463.6822 | Y46: =SUMIF($E$23:$R$23,Y$23,$E46:$R46) -> 1598.0486 | Z46: =SUMIF($E$23:$R$23,Z$23,$E46:$R46) -> 1865.1181 | AA46: =SUMIF($E$23:$R$23,AA$23,$E46:$R46) -> 2178.9601
C47: Yield (Revenue per RPK): | D47: p / KM | E47: =E46/E$40*Units -> 1.1510057 | F47: =F46/F$40*Units -> 1.367917 | G47: =G46/G$40*Units -> 1.279124 | H47: =H46/H$40*Units -> 0.98161811 | I47: =I46/I$40*Units -> 1.3629283 | J47: =J46/J$40*Units -> 2.1020696 | K47: =K46/K$40*Units -> 1.9133938 | L47: 1.75 | M47: 1.55 | N47: 1.35 | O47: 1.15 | P47: 1.4 | Q47: 1.3 | R47: 1.35 | T47: =T46/T$40*Units -> 1.2771368 | U47: =U46/U$40*Units -> 1.1983569 | V47: =V46/V$40*Units -> 1.9411715 | W47: =W46/W$40*Units -> 1.8147983 | X47: =X46/X$40*Units -> 1.431698 | Y47: =Y46/Y$40*Units -> 1.2938965 | Z47: =Z46/Z$40*Units -> 1.3 | AA47: =AA46/AA$40*Units -> 1.35
B49: Expense Drivers: | E49: =$E$26 -> 43555 | F49: =$F$26 -> 43738 | G49: =$G$26 -> 43921 | H49: =$H$26 -> 44104 | I49: =$I$26 -> 44286 | J49: =$J$26 -> 44469 | K49: =$K$26 -> 44651 | L49: =$L$26 -> 44834 | M49: =$M$26 -> 45016 | N49: =$N$26 -> 45199 | O49: =$O$26 -> 45382 | P49: =$P$26 -> 45565 | Q49: =$Q$26 -> 45930 | R49: =$R$26 -> 46295 | T49: =$T$26 -> 43738 | U49: =$U$26 -> 44104 | V49: =$V$26 -> 44469 | W49: =$W$26 -> 44834 | X49: =$X$26 -> 45199 | Y49: =$Y$26 -> 45565 | Z49: =$Z$26 -> 45930 | AA49: =$AA$26 -> 46295
C51: Non-Fuel Costs per ASK: | D51: p per ASK | E51: =-E95/E29*Units -> 3.5590577 | F51: =-F95/F29*Units -> 3.3618738 | G51: =-G95/G29*Units -> 3.7623254 | H51: =-H95/H29*Units -> 5.5171985 | I51: =-I95/I29*Units -> 6.5158259 | J51: =-J95/J29*Units -> 3.8994458 | K51: =-K95/K29*Units -> 3.9577683 | L51: 3.5 | M51: 3.7 | N51: 3.45 | O51: 3.6 | P51: 3.5 | Q51: 3.55 | R51: 3.6 | T51: =-T95/T29*Units -> 3.4457503 | U51: =-U95/U29*Units -> 4.211364 | V51: =-V95/V29*Units -> 4.534005 | W51: =-W95/W29*Units -> 3.6907549 | X51: =-X95/X29*Units -> 3.5541765 | Y51: =-Y95/Y29*Units -> 3.5427086 | Z51: =-Z95/Z29*Units -> 3.55 | AA51: =-AA95/AA29*Units -> 3.6
C53: Selected Fuel Costs per ASK: | D53: p per ASK | E53: =-E96/E29*Units -> 1.2194381 | F53: =-F96/F29*Units -> 1.2205911 | G53: =-G96/G29*Units -> 1.1421727 | H53: =-H96/H29*Units -> 1.1631523 | I53: =-I96/I29*Units -> 1.1993076 | J53: =-J96/J29*Units -> 1.0847189 | K53: =-K96/K29*Units -> 1.0557937 | L53: =INDEX(L54:L56,MATCH(Scenario,$C54:$C56,0),1) -> 1.1 | M53: =INDEX(M54:M56,MATCH(Scenario,$C54:$C56,0),1) -> 1.12 | N53: =INDEX(N54:N56,MATCH(Scenario,$C54:$C56,0),1) -> 1.12 | O53: =INDEX(O54:O56,MATCH(Scenario,$C54:$C56,0),1) -> 1.15 | P53: =INDEX(P54:P56,MATCH(Scenario,$C54:$C56,0),1) -> 1.2 | Q53: =INDEX(Q54:Q56,MATCH(Scenario,$C54:$C56,0),1) -> 1.2 | R53: =INDEX(R54:R56,MATCH(Scenario,$C54:$C56,0),1) -> 1.22 | T53: =-T96/T29*Units -> 1.2201006 | U53: =-U96/U29*Units -> 1.147541 | V53: =-V96/V29*Units -> 1.1125105 | W53: =-W96/W29*Units -> 1.081579 | X53: =-X96/X29*Units -> 1.12 | Y53: =-Y96/Y29*Units -> 1.1786457 | Z53: =-Z96/Z29*Units -> 1.2 | AA53: =-AA96/AA29*Units -> 1.22
C54: =$C$31 -> Base | D54: p per ASK | L54: 1.1 | M54: 1.12 | N54: 1.12 | O54: 1.15 | P54: 1.2 | Q54: 1.2 | R54: 1.22
C55: =$C$32 -> Downside | D55: p per ASK | L55: 1.12 | M55: 1.15 | N55: 1.2 | O55: 1.25 | P55: 1.3 | Q55: 1.35 | R55: 1.4
...

Sheet DCF
B2: ="DCF Analysis - "&Company_Name -> DCF Analysis - easyJet plc
B3: =Public_Comps!$B$3 -> (£ GBP in Millions Except Per Share Amounts in GBP as Stated)
B6: =Company_Name&" - DCF Assumptions & Output:" -> easyJet plc - DCF Assumptions & Output: | D6: Units:
C8: Operating Scenario: | D8: Name | E8: Base | H8: Terminal Value - Multiples Method: | M8: Terminal Value - Perpetuity Growth Method:
C9: Company Name: | D9: Name | E9: =Company_Name -> easyJet plc
H10: Median CY23 TEV / EBITDA of Comps: | K10: =Public_Comps!S38 -> 5.8767237 | M10: Expected Long-Term GDP Growth: | P10: 0.02
C11: Valuation Date: | D11: Date | E11: =TODAY() -> 45765 | H11: Median CY23 TEV / EBITDA of Target: | K11: =Public_Comps!S42 -> 4.7911753
C12: Stub Period Fraction: | D12: # | E12: =_xlfn.DAYS(H43,Val_Date)/_xlfn.DAYS(H43,G43) -> -2.5506849
H13: Baseline Terminal EBITDA Multiple: | K13: =INDEX(K14:K16,MATCH(Scenario,$H14:$H16,0),1) -> 4.8960241 | M13: Baseline Terminal FCF Growth Rate: | P13: =INDEX(P14:P16,MATCH(Scenario,$M14:$M16,0),1) -> 0.01
C14: Current Share Price: | D14: £ / Share | E14: 4.531 | H14: =EZJ!$C$31 -> Base | K14: 4.8960241 | M14: =EZJ!$C$31 -> Base | P14: 0.01
C15: Diluted Shares Outstanding: | D15: M Shares | E15: 759 | H15: =EZJ!$C$32 -> Downside | K15: 4.3090372 | M15: =EZJ!$C$32 -> Downside | P15: 0.005
H16: =EZJ!$C$33 -> XT Downside | K16: 3.8878596 | M16: =EZJ!$C$33 -> XT Downside | P16: 0
C17: Discount Rate (WACC): | D17: % | E17: =WACC!L41 -> 0.11585847
H18: Baseline Terminal Value: | K18: =K13*Q135 -> 11341.839 | M18: Baseline Terminal Value: | P18: =Q122*(1+P13)/(Discount_Rate-P13) -> 7644.4092
C19: Current Equity Value: | D19: £ M | E19: =Share_Price*Diluted_Shares -> 3439.029 | H19: Implied Terminal FCF Growth Rate: | K19: =(K18*Discount_Rate-Q122)/(K18+Q122) -> 0.042232773 | M19: Implied Terminal EBITDA Multiple: | P19: =P18/Q135 -> 3.2999245
C20: (-) Cash & Investments: | D20: £ M | E20: =-EZJ!K119 -> -3505
C21: (-) Net Operating Losses: | D21: £ M | E21: =-EZJ!K83*Tax_Rate -> -608.94246 | H21: (+) PV of Terminal Value: | K21: =K18*Q129 -> 5592.9032 | M21: (+) PV of Terminal Value: | P21: =P18*Q130 -> 3982.0097
C22: (+) Total Debt: | D22: £ M | E22: =EZJ!K131 -> 3046 | H22: (+) PV of Year 10 NOL Balance: | K22: =$Q$102*Tax_Rate*$Q$129 -> 0 | M22: (+) PV of Year 10 NOL Balance: | P22: =$Q$102*Tax_Rate*$Q$130 -> 0
C23: (+) Preferred Stock: | D23: £ M | E23: 0 | H23: (+) PV of UFCFs: | K23: =SUM($H$127:$Q$127) -> 1417.8541 | M23: (+) PV of UFCFs: | P23: =SUM($H$127:$Q$127) -> 1417.8541
C24: (+) Finance & Operating Leases: | D24: £ M | E24: =EZJ!K130 -> 1055 | H24: Implied Enterprise Value: | K24: =SUM(K21:K23) -> 7010.7573 | M24: Implied Enterprise Value: | P24: =SUM(P21:P23) -> 5399.8638
C25: (+) Noncontrolling Interests: | D25: £ M | E25: 0
C26: (+) Unfunded Pensions: | D26: £ M | E26: 0 | H26: % of Implied TEV from Terminal Value: | K26: =K21/K24 -> 0.7977602 | M26: % of Implied TEV from Terminal Value: | P26: =P21/P24 -> 0.7374278
C27: Current Enterprise Value Incl. Leases: | D27: £ M | E27: =SUM(E19:E26) -> 3426.0865
H28: (+) Cash & Investments: | K28: =-E20 -> 3505 | M28: =H28 -> (+) Cash & Investments: | P28: =K28 -> 3505
E29: P/E | F29: =Share_Price/F33 -> -37.345067 | H29: (+) Net Operating Losses: | K29: 0 | M29: =H29 -> (+) Net Operating Losses: | P29: 0
E30: P/B | F30: =Share_Price/F35 -> 0.61903618 | H30: (-) Total Debt: | K30: =-E22 -> -3046 | M30: =H30 -> (-) Total Debt: | P30: =K30 -> -3046
E31: TTM EPS | F31: =SUM(EZJ!O114:P114)/Diluted_Shares -> 0.36225742 | H31: (-) Preferred Stock: | K31: =-E23 -> 0 | M31: =H31 -> (-) Preferred Stock: | P31: =K31 -> 0
E32: Last Year EPS | F32: =SUM(EZJ!O114:P114)/Diluted_Shares -> 0.36225742 | H32: (-) Finance & Operating Leases: | K32: 0 | M32: =H32 -> (-) Finance & Operating Leases: | P32: 0
E33: 10 Yr Avg EPS | F33: =AVERAGE(EZJ!E114:Q114)/Diluted_Shares -> -0.12132794 | H33: (-) Noncontrolling Interests: | K33: =-E25 -> 0 | M33: =H33 -> (-) Noncontrolling Interests: | P33: =K33 -> 0
E34: FWRD 12 M EPS | F34: =SUM(EZJ!Q114:R114)/Diluted_Shares -> 1.077134 | H34: (-) Unfunded Pensions: | K34: =-E26 -> 0 | M34: =H34 -> (-) Unfunded Pensions: | P34: =K34 -> 0
E35: BVPS | F35: =F36/K37 -> 7.319443 | H35: Implied Equity Value: | K35: =K24+SUM(K28:K34) -> 7469.7573 | M35: Implied Equity Value: | P35: =P24+SUM(P28:P34) -> 5858.8638
E36: Shareholders Equity | F36: =SUM(EZJ!O124,EZJ!P124)-SUM(EZJ!O132:'EZJ'!P132) -> 5555.4572
H37: Diluted Shares Outstanding: | K37: =Diluted_Shares -> 759 | M37: Diluted Shares Outstanding: | P37: =Diluted_Shares -> 759
H39: Implied Share Price from DCF: | K39: =MAX(0,K35/K37) -> 9.8415775 | L39: =K35/758 -> 9.8545611 | M39: Implied Share Price from DCF: | P39: =MAX(0,P35/P37) -> 7.7191882
H40: Premium / (Discount) to Current: | K40: =K39/Share_Price-1 -> 1.1720542 | M40: Premium / (Discount) to Current: | P40: =P39/Share_Price-1 -> 0.70363897
G42: Historical: | J42: 0
B43: Assumptions and Drivers: | D43: =$D$6 -> Units: | E43: =EZJ!T26 -> 43738 | F43: =EZJ!U26 -> 44104 | G43: =EZJ!V26 -> 44469 | H43: =EZJ!W26 -> 44834 | I43: =EZJ!X26 -> 45199 | J43: =EZJ!Y26 -> 45565 | K43: =EZJ!Z26 -> 45930 | L43: =EZJ!AA26 -> 46295 | M43: =EOMONTH(L43,12) -> 46660 | N43: =EOMONTH(M43,12) -> 47026 | O43: =EOMONTH(N43,12) -> 47391 | P43: =EOMONTH(O43,12) -> 47756 | Q43: =EOMONTH(P43,12) -> 48121
C45: Available Seat Kilometres (ASK): | D45: Millions KM | E45: =EZJ!T29 -> 116056 | F45: =EZJ!U29 -> 62830 | G45: =EZJ!V29 -> 33348 | H45: =EZJ!W29 -> 82281 | I45: =EZJ!X29 -> 115193.4 | J45: =EZJ!Y29 -> 134872.5 | K45: =EZJ!Z29 -> 155103.37 | L45: =EZJ!AA29 -> 174491.3 | M45: =L45*(1+M46) -> 191940.43 | N45: =M45*(1+N46) -> 211134.47 | O45: =N45*(1+O46) -> 226969.55 | P45: =O45*(1+P46) -> 238318.03 | Q45: =P45*(1+Q46) -> 250233.93
C46: Selected YoY Growth Rate: | D46: % | E46: =EZJ!T30 -> 0 | F46: =EZJ!U30 -> -0.45862342 | G46: =EZJ!V30 -> -0.46923444 | H46: =EZJ!W30 -> 1.4673444 | I46: =EZJ!X30 -> 0.4 | J46: =EZJ!Y30 -> 0.17083531 | K46: =EZJ!Z30 -> 0.15 | L46: =EZJ!AA30 -> 0.125 | M46: =INDEX(M47:M49,MATCH(Scenario,$C47:$C49,0),1) -> 0.1 | N46: =INDEX(N47:N49,MATCH(Scenario,$C47:$C49,0),1) -> 0.1 | O46: =INDEX(O47:O49,MATCH(Scenario,$C47:$C49,0),1) -> 0.075 | P46: =INDEX(P47:P49,MATCH(Scenario,$C47:$C49,0),1) -> 0.05 | Q46: =INDEX(Q47:Q49,MATCH(Scenario,$C47:$C49,0),1) -> 0.05
C47: =EZJ!$C$31 -> Base | D47: % | M47: 0.1 | N47: 0.1 | O47: 0.075 | P47: 0.05 | Q47: 0.05
...

Sheet Graphs
B2: =Company_Name&" - Valuation Graphs and Analysis" -> easyJet plc - Valuation Graphs and Analysis
P4: ="Annual Revenue, "&Public_Comps!$P$8&" - "&Public_Comps!$Q$8 -> Annual Revenue, CY 23 - CY 24 | Q4: =Public_Comps!P8 -> CY 23 | R4: =Public_Comps!Q8 -> CY 24
P5: ="Annual EBITDA, "&Public_Comps!$P$8&" - "&Public_Comps!$Q$8 -> Annual EBITDA, CY 23 - CY 24 | Q5: =Public_Comps!S8 -> CY 23 | R5: =Public_Comps!T8 -> CY 24
P19: ="2-Year Revenue CAGR, "&Public_Comps!$O$8&" - "&Public_Comps!$Q$8 -> 2-Year Revenue CAGR, CY 22 - CY 24
P20: ="2-Year EBITDA CAGR, "&Public_Comps!$O$8&" - "&Public_Comps!$Q$8 -> 2-Year EBITDA CAGR, CY 22 - CY 24
P22: =Public_Comps!$Q$8&" Revenue Multiples" -> CY 24 Revenue Multiples
P23: =Public_Comps!$Q$8&" EBITDA Multiples" -> CY 24 EBITDA Multiples
P29: Supporting Data (Sorted by revenue in ascending order):
Q30: Revenue: | T30: EBITDA: | W30: Rev. Multiples: | Z30: EBITDA Multiples:
Q31: =Public_Comps!P8 -> CY 23 | R31: =Public_Comps!Q8 -> CY 24 | T31: =Public_Comps!S8 -> CY 23 | U31: =Public_Comps!T8 -> CY 24 | W31: =Public_Comps!P27 -> CY 23 | X31: =Public_Comps!Q27 -> CY 24 | Z31: =Public_Comps!S27 -> CY 23 | AA31: =Public_Comps!T27 -> CY 24
P32: ISE:RYA | Q32: =Public_Comps!P9 -> 10051.66 | R32: =Public_Comps!Q9 -> 11420.625 | T32: =Public_Comps!S9 -> 2036.42 | U32: =Public_Comps!T9 -> 2520.765 | W32: =Public_Comps!P28 -> 1.3227395 | X32: =Public_Comps!Q28 -> 1.1641857 | Z32: =Public_Comps!S28 -> 6.5289714 | AA32: =Public_Comps!T28 -> 5.2744814
P33: =Ticker -> LSE:EZJ | Q33: =Public_Comps!P23 -> 6310.6335 | R33: =Public_Comps!Q23 -> 6940.9992 | T33: =Public_Comps!S23 -> 715.0827 | U33: =Public_Comps!T23 -> 853.71559 | W33: =Public_Comps!P42 -> 0.54290691 | X33: =Public_Comps!Q42 -> 0.49360134 | Z33: =Public_Comps!S42 -> 4.7911753 | AA33: =Public_Comps!T42 -> 4.0131475
P34: AIM:JET2 | Q34: =Public_Comps!P11 -> 5088.5175 | R34: =Public_Comps!Q11 -> 5518.4125 | T34: =Public_Comps!S11 -> 552.4775 | U34: =Public_Comps!T11 -> 612.495 | W34: =Public_Comps!P30 -> 0.28336257 | X34: =Public_Comps!Q30 -> 0.26128808 | Z34: =Public_Comps!S30 -> 2.6098717 | AA34: =Public_Comps!T30 -> 2.3541342
P35: LSE:WIZZ | Q35: =Public_Comps!P10 -> 4282.335 | R35: =Public_Comps!Q10 -> 5352.865 | T35: =Public_Comps!S10 -> 731.735 | U35: =Public_Comps!T10 -> 1154.165 | W35: =Public_Comps!P29 -> 1.1623855 | X35: =Public_Comps!Q29 -> 0.92991772 | Z35: =Public_Comps!S29 -> 6.8026321 | AA35: =Public_Comps!T29 -> 4.3128357
P36: IBSE:PGSUS | Q36: =Public_Comps!P13 -> 2412.22 | R36: =Public_Comps!Q13 -> 2915.87 | T36: =Public_Comps!S13 -> 755.68 | U36: =Public_Comps!T13 -> 1038.98 | W36: =Public_Comps!P32 -> 1.1298667 | X36: =Public_Comps!Q32 -> 0.93470799 | Z36: =Public_Comps!S32 -> 3.6066682 | AA36: =Public_Comps!T32 -> 2.6232334
P37: OB:NAS | Q37: =Public_Comps!P14 -> 2070.58 | R37: =Public_Comps!Q14 -> 2295.52 | T37: =Public_Comps!S14 -> 282.04 | U37: =Public_Comps!T14 -> 416.77 | W37: =Public_Comps!P33 -> 0.49092525 | X37: =Public_Comps!Q33 -> 0.44281906 | Z37: =Public_Comps!S33 -> 3.6040987 | AA37: =Public_Comps!T33 -> 2.4389951
P38: DFM:AIRARABIA | Q38: =Public_Comps!P12 -> 1214.1 | R38: =Public_Comps!Q12 -> 1259.29 | T38: =Public_Comps!S12 -> 366.08 | U38: =Public_Comps!T12 -> 380.18 | W38: =Public_Comps!P31 -> 1.7719718 | X38: =Public_Comps!Q31 -> 1.7083841 | Z38: =Public_Comps!S31 -> 5.8767237 | AA38: =Public_Comps!T31 -> 5.6587695
P39: KWSE:JAZEERA | Q39: =Public_Comps!P15 -> 484.55 | R39: =Public_Comps!Q15 -> 538.03 | T39: =Public_Comps!S15 -> 144.55 | U39: =Public_Comps!T15 -> 181.01 | W39: =Public_Comps!P34 -> 3.1771747 | X39: =Public_Comps!Q34 -> 2.8613646 | Z39: =Public_Comps!S34 -> 10.650294 | AA39: =Public_Comps!T34 -> 8.505055
P41: Data for Graphs (Sorted by Revenue CAGR in ascending order):
Q42: 2-Year Revenue CAGR: | T42: 2-Year EBITDA CAGR: | W42: Year 2 Rev. Multiple: | Z42: Year 2 EBITDA Multiple:
Q43: =Public_Comps!X8 -> CAGR | T43: =Public_Comps!Y8 -> CAGR | W43: =Public_Comps!Q27 -> CY 24 | Z43: =Public_Comps!T27 -> CY 24
P44: LSE:WIZZ | Q44: =Public_Comps!X10 -> 0.35609389 | R44: =IF($P44=Ticker,Q44,NA()) -> #N/A | T44: =Public_Comps!Y10 -> 2.2150308 | U44: =IF($P44=Ticker,T44,NA()) -> #N/A | W44: =Public_Comps!Q29 -> 0.92991772 | X44: =IF($P44=Ticker,W44,NA()) -> #N/A | Z44: =Public_Comps!T29 -> 4.3128357 | AA44: =IF($P44=Ticker,Z44,NA()) -> #N/A
P45: IBSE:PGSUS | Q45: =Public_Comps!X13 -> 0.33824061 | R45: =IF($P45=Ticker,Q45,NA()) -> #N/A | T45: =Public_Comps!Y13 -> 0.50914411 | U45: =IF($P45=Ticker,T45,NA()) -> #N/A | W45: =Public_Comps!Q32 -> 0.93470799 | X45: =IF($P45=Ticker,W45,NA()) -> #N/A | Z45: =Public_Comps!T32 -> 2.6232334 | AA45: =IF($P45=Ticker,Z45,NA()) -> #N/A
P46: LSE:EZJ | Q46: =Public_Comps!X23 -> 0.23664954 | R46: =IF($P46=Ticker,Q46,NA()) -> 0.23664954 | T46: =Public_Comps!Y23 -> 0.64730732 | U46: =IF($P46=Ticker,T46,NA()) -> 0.64730732 | W46: =Public_Comps!Q42 -> 0.49360134 | X46: =IF($P46=Ticker,W46,NA()) -> 0.49360134 | Z46: =Public_Comps!T42 -> 4.0131475 | AA46: =IF($P46=Ticker,Z46,NA()) -> 4.0131475
P47: ISE:RYA | Q47: =Public_Comps!X9 -> 0.22872902 | R47: =IF($P47=Ticker,Q47,NA()) -> #N/A | T47: =Public_Comps!Y9 -> 0.28648528 | U47: =IF($P47=Ticker,T47,NA()) -> #N/A | W47: =Public_Comps!Q28 -> 1.1641857 | X47: =IF($P47=Ticker,W47,NA()) -> #N/A | Z47: =Public_Comps!T28 -> 5.2744814 | AA47: =IF($P47=Ticker,Z47,NA()) -> #N/A
P48: OB:NAS | Q48: =Public_Comps!X14 -> 0.21358172 | R48: =IF($P48=Ticker,Q48,NA()) -> #N/A | T48: =Public_Comps!Y14 -> N/A | U48: =IF($P48=Ticker,T48,NA()) -> #N/A | W48: =Public_Comps!Q33 -> 0.44281906 | X48: =IF($P48=Ticker,W48,NA()) -> #N/A | Z48: =Public_Comps!T33 -> 2.4389951 | AA48: =IF($P48=Ticker,Z48,NA()) -> #N/A
P49: AIM:JET2 | Q49: =Public_Comps!X11 -> 0.19873318 | R49: =IF($P49=Ticker,Q49,NA()) -> #N/A | T49: =Public_Comps!Y11 -> 0.32795467 | U49: =IF($P49=Ticker,T49,NA()) -> #N/A | W49: =Public_Comps!Q30 -> 0.26128808 | X49: =IF($P49=Ticker,W49,NA()) -> #N/A | Z49: =Public_Comps!T30 -> 2.3541342 | AA49: =IF($P49=Ticker,Z49,NA()) -> #N/A
P50: KWSE:JAZEERA | Q50: =Public_Comps!X15 -> 0.15806679 | R50: =IF($P50=Ticker,Q50,NA()) -> #N/A | T50: =Public_Comps!Y15 -> 0.24836527 | U50: =IF($P50=Ticker,T50,NA()) -> #N/A | W50: =Public_Comps!Q34 -> 2.8613646 | X50: =IF($P50=Ticker,W50,NA()) -> #N/A | Z50: =Public_Comps!T34 -> 8.505055 | AA50: =IF($P50=Ticker,Z50,NA()) -> #N/A
P51: DFM:AIRARABIA | Q51: =Public_Comps!X12 -> 0.07199625 | R51: =IF($P51=Ticker,Q51,NA()) -> #N/A | T51: =Public_Comps!Y12 -> 0.03259097 | U51: =IF($P51=Ticker,T51,NA()) -> #N/A | W51: =Public_Comps!Q31 -> 1.7083841 | X51: =IF($P51=Ticker,W51,NA()) -> #N/A | Z51: =Public_Comps!T31 -> 5.6587695 | AA51: =IF($P51=Ticker,Z51,NA()) -> #N/A
B82: =DCF!E43 -> 43738 | C82: =DCF!F43 -> 44104 | D82: =DCF!G43 -> 44469 | E82: =DCF!H43 -> 44834 | F82: =DCF!I43 -> 45199 | G82: =DCF!J43 -> 45565 | H82: =DCF!K43 -> 45930 | I82: =DCF!L43 -> 46295 | ... N82: =DCF!Q43 -> 48121
B83: 116056 | C83: 62830 | D83: 33348 | E83: 82281 | F83: 115193.4 | G83: 134872.5 | H83: 155103.37 | I83: 174491.3 | J83: 191940.43 | K83: 211134.47 | L83: 226969.55 | M83: 238318.03 | N83: 250233.93
B84: 116056 | C84: 62830 | D84: 33348 | E84: 69651 | F84: 92260.65 | G84: 115325.81 | H84: 135507.83 | I84: 152446.31 | J84: 167690.94 | K84: 184460.03 | L84: 198294.54 | M84: 213166.63 | N84: 223824.96
B85: 116056 | C85: 62830 | D85: 33348 | E85: 67125 | F85: 85620.6 | G85: 100692.34 | H85: 113278.89 | I85: 124606.78 | J85: 137067.45 | K85: 150774.2 | L85: 165851.62 | M85: 182436.78 | N85: 196119.54
B117: =DCF!E43 -> 43738 | C117: =DCF!F43 -> 44104 | D117: =DCF!G43 -> 44469 | E117: =DCF!H43 -> 44834 | F117: =DCF!I43 -> 45199 | G117: =DCF!J43 -> 45565 | H117: =DCF!K43 -> 45930 | I117: =DCF!L43 -> 46295 | ... N117: =DCF!Q43 -> 48121
B118: 970 | C118: -358 | D118: -425 | E118: 222.9445 | F118: 701.42619 | G118: 978.69196 | H118: 1169.0917 | I118: 1435.1909 | J118: 1689.2557 | K118: 1947.1876 | L118: 2079.6085 | M118: 2171.0773 | N118: 2316.5406
B119: 970 | C119: -358 | D119: -425 | E119: 99.0442 | F119: 335.55186 | G119: 542.39064 | H119: 777.81494 | I119: 932.97141 | J119: 1140.4556 | K119: 1276.9246 | L119: 1420.2846 | M119: 1558.248 | N119: 1669.1746
B120: 970 | C120: -358 | D120: -425 | E120: 66.3325 | F120: 213.4941 | G120: 228.4144 | H120: 402.14005 | I120: 561.97656 | J120: 795.11974 | K120: 892.9602 | L120: 1022.0606 | M120: 1151.1761 | N120: 1266.4419

Sheet WACC
B2: ="WACC Analysis - "&Company_Name -> WACC Analysis - easyJet plc
B3: =Public_Comps!$B$3 -> (£ GBP in Millions Except Per Share Amounts in GBP as Stated)
B5: Discount Rate Calculations - Assumptions:
B6: Risk-Free Rate: | F6: 0.0452
B7: Equity Risk Premium: | F7: 0.065
B8: Pre-Tax Cost of Debt: | F8: =EZJ!K187 -> 0.05
B9: Cost of Preferred Stock: | F9: 0
B11: =Public_Comps!$B$8 -> Company Name | D11: =Public_Comps!$G$8 -> Beta | E11: =Public_Comps!$J$8 -> Debt | G11: =Public_Comps!$L$8 -> Preferred | I11: =Public_Comps!$F$8 -> Value | K11: =Public_Comps!$H$8 -> Tax Rate
B12: Comparable Companies - Unlevered Beta Calculation:
D13: Levered | G13: Preferred | I13: Equity | L13: Unlevered
B14: Name | C14: Ticker | D14: Beta | E14: Debt | F14: % Debt | G14: Stock | H14: % Preferred | I14: Value | J14: % Equity | K14: Tax Rate | L14: Beta
B15: =INDEX(Pub_Comps_Data,MATCH(WACC!$C15,Ticker_Range,0),MATCH(WACC!B$11,Pub_Comps_Info_Range,0)) -> Ryanair Holdings plc | C15: ISE:RYA | D15: =INDEX(Pub_Comps_Data,MATCH(WACC!$C15,Ticker_Range,0),MATCH(WACC!D$11,Pub_Comps_Info_Range,0)) -> 1.48 | E15: =INDEX(Pub_Comps_Data,MATCH(WACC!$C15,Ticker_Range,0),MATCH(WACC!E$11,Pub_Comps_Info_Range,0)) -> 4253.5 | F15: =E15/($E15+$G15+$I15) -> 0.24753501 | G15: =INDEX(Pub_Comps_Data,MATCH(WACC!$C15,Ticker_Range,0),MATCH(WACC!G$11,Pub_Comps_Info_Range,0)) -> 0 | H15: =G15/($E15+$G15+$I15) -> 0 | I15: =INDEX(Pub_Comps_Data,MATCH(WACC!$C15,Ticker_Range,0),MATCH(WACC!I$11,Pub_Comps_Info_Range,0)) -> 12929.928 | J15: =I15/($E15+$G15+$I15) -> 0.75246499 | K15: =INDEX(Pub_Comps_Data,MATCH(WACC!$C15,Ticker_Range,0),MATCH(WACC!K$11,Pub_Comps_Info_Range,0)) -> 0.15 | L15: =D15/(1+E15/I15*(1-K15)+G15/I15) -> 1.1565928
B16: =INDEX(Pub_Comps_Data,MATCH(WACC!$C16,Ticker_Range,0),MATCH(WACC!B$11,Pub_Comps_Info_Range,0)) -> Wizz Air Holdings Plc | C16: LSE:WIZZ | D16: =INDEX(Pub_Comps_Data,MATCH(WACC!$C16,Ticker_Range,0),MATCH(WACC!D$11,Pub_Comps_Info_Range,0)) -> 1.94 | E16: =INDEX(Pub_Comps_Data,MATCH(WACC!$C16,Ticker_Range,0),MATCH(WACC!E$11,Pub_Comps_Info_Range,0)) -> 897.08 | F16: =E16/($E16+$G16+$I16) -> 0.25557078 | G16: =INDEX(Pub_Comps_Data,MATCH(WACC!$C16,Ticker_Range,0),MATCH(WACC!G$11,Pub_Comps_Info_Range,0)) -> 0 | H16: =G16/($E16+$G16+$I16) -> 0 | I16: =INDEX(Pub_Comps_Data,MATCH(WACC!$C16,Ticker_Range,0),MATCH(WACC!I$11,Pub_Comps_Info_Range,0)) -> 2613.024 | J16: =I16/($E16+$G16+$I16) -> 0.74442922 | K16: =INDEX(Pub_Comps_Data,MATCH(WACC!$C16,Ticker_Range,0),MATCH(WACC!K$11,Pub_Comps_Info_Range,0)) -> 0.15 | L16: =D16/(1+E16/I16*(1-K16)+G16/I16) -> 1.5017637
B17: =INDEX(Pub_Comps_Data,MATCH(WACC!$C17,Ticker_Range,0),MATCH(WACC!B$11,Pub_Comps_Info_Range,0)) -> Jet2 plc | C17: AIM:JET2 | D17: =INDEX(Pub_Comps_Data,MATCH(WACC!$C17,Ticker_Range,0),MATCH(WACC!D$11,Pub_Comps_Info_Range,0)) -> 2.21 | E17: =INDEX(Pub_Comps_Data,MATCH(WACC!$C17,Ticker_Range,0),MATCH(WACC!E$11,Pub_Comps_Info_Range,0)) -> 991.7 | F17: =E17/($E17+$G17+$I17) -> 0.32074177 | G17: =INDEX(Pub_Comps_Data,MATCH(WACC!$C17,Ticker_Range,0),MATCH(WACC!G$11,Pub_Comps_Info_Range,0)) -> 0 | H17: =G17/($E17+$G17+$I17) -> 0 | I17: =INDEX(Pub_Comps_Data,MATCH(WACC!$C17,Ticker_Range,0),MATCH(WACC!I$11,Pub_Comps_Info_Range,0)) -> 2100.1954 | J17: =I17/($E17+$G17+$I17) -> 0.67925823 | K17: =INDEX(Pub_Comps_Data,MATCH(WACC!$C17,Ticker_Range,0),MATCH(WACC!K$11,Pub_Comps_Info_Range,0)) -> 0.25 | L17: =D17/(1+E17/I17*(1-K17)+G17/I17) -> 1.6320254
B18: =INDEX(Pub_Comps_Data,MATCH(WACC!$C18,Ticker_Range,0),MATCH(WACC!B$11,Pub_Comps_Info_Range,0)) -> Pegasus Hava Tasimaciligi Anonim Sirketi | C18: IBSE:PGSUS | D18: =INDEX(Pub_Comps_Data,MATCH(WACC!$C18,Ticker_Range,0),MATCH(WACC!D$11,Pub_Comps_Info_Range,0)) -> 1.69 | E18: =INDEX(Pub_Comps_Data,MATCH(WACC!$C18,Ticker_Range,0),MATCH(WACC!E$11,Pub_Comps_Info_Range,0)) -> 445.98496 | F18: =E18/($E18+$G18+$I18) -> 0.33407815 | G18: =INDEX(Pub_Comps_Data,MATCH(WACC!$C18,Ticker_Range,0),MATCH(WACC!G$11,Pub_Comps_Info_Range,0)) -> 0 | H18: =G18/($E18+$G18+$I18) -> 0 | I18: =INDEX(Pub_Comps_Data,MATCH(WACC!$C18,Ticker_Range,0),MATCH(WACC!I$11,Pub_Comps_Info_Range,0)) -> 888.987 | J18: =I18/($E18+$G18+$I18) -> 0.66592185 | K18: =INDEX(Pub_Comps_Data,MATCH(WACC!$C18,Ticker_Range,0),MATCH(WACC!K$11,Pub_Comps_Info_Range,0)) -> 0.2 | L18: =D18/(1+E18/I18*(1-K18)+G18/I18) -> 1.2059867
B19: =INDEX(Pub_Comps_Data,MATCH(WACC!$C19,Ticker_Range,0),MATCH(WACC!B$11,Pub_Comps_Info_Range,0)) -> Air Arabia PJSC | C19: DFM:AIRARABIA | D19: =INDEX(Pub_Comps_Data,MATCH(WACC!$C19,Ticker_Range,0),MATCH(WACC!D$11,Pub_Comps_Info_Range,0)) -> 0.67 | E19: =INDEX(Pub_Comps_Data,MATCH(WACC!$C19,Ticker_Range,0),MATCH(WACC!E$11,Pub_Comps_Info_Range,0)) -> 23.3344 | F19: =E19/($E19+$G19+$I19) -> 0.0093461515 | G19: =INDEX(Pub_Comps_Data,MATCH(WACC!$C19,Ticker_Range,0),MATCH(WACC!G$11,Pub_Comps_Info_Range,0)) -> 0 | H19: =G19/($E19+$G19+$I19) -> 0 | I19: =INDEX(Pub_Comps_Data,MATCH(WACC!$C19,Ticker_Range,0),MATCH(WACC!I$11,Pub_Comps_Info_Range,0)) -> 2473.351 | J19: =I19/($E19+$G19+$I19) -> 0.99065385 | K19: =INDEX(Pub_Comps_Data,MATCH(WACC!$C19,Ticker_Range,0),MATCH(WACC!K$11,Pub_Comps_Info_Range,0)) -> 0.09 | L19: =D19/(1+E19/I19*(1-K19)+G19/I19) -> 0.66429685
B20: =INDEX(Pub_Comps_Data,MATCH(WACC!$C20,Ticker_Range,0),MATCH(WACC!B$11,Pub_Comps_Info_Range,0)) -> Norwegian Air Shuttle ASA | C20: OB:NAS | D20: =INDEX(Pub_Comps_Data,MATCH(WACC!$C20,Ticker_Range,0),MATCH(WACC!D$11,Pub_Comps_Info_Range,0)) -> 0.99 | E20: =INDEX(Pub_Comps_Data,MATCH(WACC!$C20,Ticker_Range,0),MATCH(WACC!E$11,Pub_Comps_Info_Range,0)) -> 360.7504 | F20: =E20/($E20+$G20+$I20) -> 0.31590724 | G20: =INDEX(Pub_Comps_Data,MATCH(WACC!$C20,Ticker_Range,0),MATCH(WACC!G$11,Pub_Comps_Info_Range,0)) -> 0 | H20: =G20/($E20+$G20+$I20) -> 0 | I20: =INDEX(Pub_Comps_Data,MATCH(WACC!$C20,Ticker_Range,0),MATCH(WACC!I$11,Pub_Comps_Info_Range,0)) -> 781.2 | J20: =I20/($E20+$G20+$I20) -> 0.68409276 | K20: =INDEX(Pub_Comps_Data,MATCH(WACC!$C20,Ticker_Range,0),MATCH(WACC!K$11,Pub_Comps_Info_Range,0)) -> 0.22 | L20: =D20/(1+E20/I20*(1-K20)+G20/I20) -> 0.72783615
B21: =INDEX(Pub_Comps_Data,MATCH(WACC!$C21,Ticker_Range,0),MATCH(WACC!B$11,Pub_Comps_Info_Range,0)) -> Jazeera Airways K.S.C.P. | C21: KWSE:JAZEERA | D21: =INDEX(Pub_Comps_Data,MATCH(WACC!$C21,Ticker_Range,0),MATCH(WACC!D$11,Pub_Comps_Info_Range,0)) -> 0.85 | E21: =INDEX(Pub_Comps_Data,MATCH(WACC!$C21,Ticker_Range,0),MATCH(WACC!E$11,Pub_Comps_Info_Range,0)) -> 60.3684 | F21: =E21/($E21+$G21+$I21) -> 0.047768563 | G21: =INDEX(Pub_Comps_Data,MATCH(WACC!$C21,Ticker_Range,0),MATCH(WACC!G$11,Pub_Comps_Info_Range,0)) -> 0 | H21: =G21/($E21+$G21+$I21) -> 0 | I21: =INDEX(Pub_Comps_Data,MATCH(WACC!$C21,Ticker_Range,0),MATCH(WACC!I$11,Pub_Comps_Info_Range,0)) -> 1203.4 | J21: =I21/($E21+$G21+$I21) -> 0.95223144 | K21: =INDEX(Pub_Comps_Data,MATCH(WACC!$C21,Ticker_Range,0),MATCH(WACC!K$11,Pub_Comps_Info_Range,0)) -> 0.15 | L21: =D21/(1+E21/I21*(1-K21)+G21/I21) -> 0.81523813
B23: Median: | D23: =MEDIAN(D15:D21) -> 1.48 | E23: =MEDIAN(E15:E21) -> 445.98496 | F23: =MEDIAN(F15:F21) -> 0.25557078 | G23: =MEDIAN(G15:G21) -> 0 | H23: =MEDIAN(H15:H21) -> 0 | I23: =MEDIAN(I15:I21) -> 2100.1954 | J23: =MEDIAN(J15:J21) -> 0.74442922 | K23: =MEDIAN(K15:K21) -> 0.15 | L23: =MEDIAN(L15:L21) -> 1.1565928
B25: =Company_Name -> easyJet plc | C25: =Ticker -> LSE:EZJ | D25: =Public_Comps!G23 -> 2.45
B27: =TEXT(Company_Name,"")& " - Levered Beta & WACC Calculation:" -> easyJet plc - Levered Beta & WACC Calculation:
D28: Unlevered | G28: Preferred | I28: Equity | L28: Levered
C29: Ticker | D29: Beta | E29: Debt | F29: % Debt | G29: Stock | H29: % Preferred | I29: Value | J29: % Equity | K29: Tax Rate | L29: Beta
B30: Current Capital Structure: | C30: =Ticker -> LSE:EZJ | D30: =L23 -> 1.1565928 | E30: =INDEX(Pub_Comps_Data,MATCH(WACC!$C30,Ticker_Range,0),MATCH(WACC!E$11,Pub_Comps_Info_Range,0)) -> 3046 | F30: =E30/($E30+$G30+$I30) -> 0.46969721 | G30: =INDEX(Pub_Comps_Data,MATCH(WACC!$C30,Ticker_Range,0),MATCH(WACC!G$11,Pub_Comps_Info_Range,0)) -> 0 | H30: =G30/($E30+$G30+$I30) -> 0 | I30: =INDEX(Pub_Comps_Data,MATCH(WACC!$C30,Ticker_Range,0),MATCH(WACC!I$11,Pub_Comps_Info_Range,0)) -> 3439.029 | J30: =I30/($E30+$G30+$I30) -> 0.53030279 | K30: =INDEX(Pub_Comps_Data,MATCH(WACC!$C30,Ticker_Range,0),MATCH(WACC!K$11,Pub_Comps_Info_Range,0)) -> 0.25 | L30: =D30*(1+E30/I30*(1-K30)+G30/I30) -> 1.9249015
B31: "Optimal" Capital Structure: | C31: =Ticker -> LSE:EZJ | D31: =L23 -> 1.1565928 | E31: =($E$30+$G$30+$I$30)*F31 -> 1657.3839 | F31: =1-J31-H31 -> 0.25557078 | G31: =($E$30+$G$30+$I$30)*H31 -> 0 | H31: =H23 -> 0 | I31: =($E$30+$G$30+$I$30)*J31 -> 4827.6451 | J31: =J23 -> 0.74442922 | K31: =INDEX(Pub_Comps_Data,MATCH(WACC!$C31,Ticker_Range,0),MATCH(WACC!K$11,Pub_Comps_Info_Range,0)) -> 0.25 | L31: =D31*(1+E31/I31*(1-K31)+G31/I31) -> 1.4543961
B33: Cost of Equity Based on Comparables, Current Capital Structure: | L33: =Risk_Free_Rate+Equity_Risk_Premium*L30 -> 0.1703186
B34: Cost of Equity Based on Comparables, "Optimal" Capital Structure: | L34: =Risk_Free_Rate+Equity_Risk_Premium*L31 -> 0.13973574
B35: Cost of Equity Based on Historical Beta: | L35: =Risk_Free_Rate+Equity_Risk_Premium*D25 -> 0.20445
B37: WACC, Current Capital Structure: | L37: =L33*J30+Cost_of_Debt*(1-Tax_Rate)*F30+Cost_of_Preferred*H30 -> 0.10793408
B38: WACC, "Optimal" Capital Structure: | L38: =L34*J31+Cost_of_Debt*(1-Tax_Rate)*F31+Cost_of_Preferred*H31 -> 0.11360728
B39: WACC, Current Capital Structure and Historical Cost of Equity: | L39: =L35*J30+Cost_of_Debt*(1-Tax_Rate)*F30+Cost_of_Preferred*H30 -> 0.12603405
B41: Average WACC Produced by All Methods: | L41: =AVERAGE(L37:L39) -> 0.11585847

Sheet Public_Comps
B2: Comparable Public Companies - EMEA Low-Cost Carriers (LCCs) with LTM Revenue Above £100 Million
B3: (£ GBP in Millions Except Per Share Amounts in GBP as Stated)
B4: (Enterprise Value Includes Operating Lease and Finance Lease Liabilities; EBITDA Excludes Entire Lease Expense with IFRS Accounting)
B6: Operating Statistics: | F6: Capitalisation | X6: 2-Year | Y6: 2-Year
D7: Share | E7: Diluted | F7: Equity | K7: Total | M7: Other & | N7: Enterprise | O7: Revenue | R7: EBITDA | U7: Net Income | X7: Revenue | Y7: EBITDA | Z7: EBITDA Margin
B8: Company Name | C8: Ticker | D8: Price | E8: Shares | F8: Value | G8: Beta | H8: Tax Rate | I8: Cash | J8: Debt | K8: Leases | L8: Preferred | M8: NCI | N8: Value | O8: ="CY "&TEXT(DCF!H43,"YY") -> CY 22 | P8: ="CY "&TEXT(DCF!I43,"YY") -> CY 23 | Q8: ="CY "&TEXT(DCF!J43,"YY") -> CY 24 | R8: =$O$8 -> CY 22 | S8: =$P$8 -> CY 23 | T8: =$Q$8 -> CY 24 | U8: =$O$8 -> CY 22 | V8: =$P$8 -> CY 23 | W8: =$Q$8 -> CY 24 | X8: CAGR | Y8: CAGR | Z8: =$O$8 -> CY 22 | AA8: =$P$8 -> CY 23 | AB8: =$Q$8 -> CY 24
B9: Ryanair Holdings plc | C9: ISE:RYA | D9: 11.39 | E9: 1135.2 | F9: =D9*E9 -> 12929.928 | G9: 1.48 | H9: 0.15 | I9: -4001.3 | J9: 4253.5 | K9: 113.6 | L9: 0 | M9: 0 | N9: =F9+I9+J9+K9+L9+M9 -> 13295.728 | O9: =4154.1*(1/4)+8701.24*(3/4) -> 7564.455 | P9: =8701.24*(1/4)+10501.8*(3/4) -> 10051.66 | Q9: =10501.8*(1/4)+11726.9*(3/4) -> 11420.625 | R9: =281.5*(1/4)+1936.94*(3/4) -> 1523.08 | S9: =1936.94*(1/4)+2069.58*(3/4) -> 2036.42 | T9: =2069.58*(1/4)+2671.16*(3/4) -> 2520.765 | U9: =-208.4*(1/4)+1062.92*(3/4) -> 745.09 | V9: =1062.92*(1/4)+1131.45*(3/4) -> 1114.3175 | W9: =1131.45*(1/4)+1573.37*(3/4) -> 1462.89 | X9: =IFERROR((Q9/O9)^(1/2)-1,"N/A") -> 0.22872902 | Y9: =IFERROR((T9/R9)^(1/2)-1,"N/A") -> 0.28648528 | Z9: =R9/O9 -> 0.20134696 | AA9: =S9/P9 -> 0.20259539 | AB9: =T9/Q9 -> 0.22072041
B10: Wizz Air Holdings Plc | C10: LSE:WIZZ | D10: 25.32 | E10: 103.2 | F10: =D10*E10 -> 2613.024 | G10: 1.94 | H10: 0.15 | I10: -1052.7 | J10: 897.08 | K10: 2533.62 | L10: 0 | M10: -13.3 | N10: =F10+I10+J10+K10+L10+M10 -> 4977.724 | O10: =1439.3*(1/4)+3401.25*(3/4) -> 2910.7625 | P10: =3401.25*(1/4)+4576.03*(3/4) -> 4282.335 | Q10: =4576.03*(1/4)+5611.81*(3/4) -> 5352.865 | R10: =-342*(1/4)+262.88*(3/4) -> 111.66 | S10: =262.88*(1/4)+888.02*(3/4) -> 731.735 | T10: =888.02*(1/4)+1242.88*(3/4) -> 1154.165 | U10: =-546.7*(1/4)-495.32*(3/4) -> -508.165 | V10: =-495.32*(1/4)+233.04*(3/4) -> 50.95 | W10: =233.04*(1/4)+484.23*(3/4) -> 421.4325 | X10: =IFERROR((Q10/O10)^(1/2)-1,"N/A") -> 0.35609389 | Y10: =IFERROR((T10/R10)^(1/2)-1,"N/A") -> 2.2150308 | Z10: =R10/O10 -> 0.038361082 | AA10: =S10/P10 -> 0.1708729 | AB10: =T10/Q10 -> 0.21561631
B11: Jet2 plc | C11: AIM:JET2 | D11: 9.782 | E11: 214.7 | F11: =D11*E11 -> 2100.1954 | G11: 2.21 | H11: 0.25 | I11: -2228.5 | J11: =134.5+857.2 -> 991.7 | K11: =74.8+503.7 -> 578.5 | L11: 0 | M11: 0 | N11: =F11+I11+J11+K11+L11+M11 -> 1441.8954 | O11: =1231.7*(1/4)+4709.88*(3/4) -> 3840.335 | P11: =4709.88*(1/4)+5214.73*(3/4) -> 5088.5175 | Q11: =5214.73*(1/4)+5619.64*(3/4) -> 5518.4125 | R11: =-218.7*(1/4)+536*(3/4) -> 347.325 | S11: =536*(1/4)+557.97*(3/4) -> 552.4775 | T11: =557.97*(1/4)+630.67*(3/4) -> 612.495 | U11: =-315.4*(1/4)+227.98*(3/4) -> 92.135 | V11: =227.98*(1/4)+230.46*(3/4) -> 229.84 | W11: =230.46*(1/4)+280.1*(3/4) -> 267.69 | X11: =IFERROR((Q11/O11)^(1/2)-1,"N/A") -> 0.19873318 | Y11: =IFERROR((T11/R11)^(1/2)-1,"N/A") -> 0.32795467 | Z11: =R11/O11 -> 0.090441329 | AA11: =S11/P11 -> 0.10857337 | AB11: =T11/Q11 -> 0.11099116
B12: Air Arabia PJSC | C12: DFM:AIRARABIA | D12: 0.53 | E12: 4666.7 | F12: =D12*E12 -> 2473.351 | G12: 0.67 | H12: 0.09 | I12: -1025.3 | J12: =703.3-K12 -> 23.3344 | K12: =(591.8+2241.39)*0.24 -> 679.9656 | L12: 0 | M12: 0 | N12: =F12+I12+J12+K12+L12+M12 -> 2151.351 | O12: 1095.82 | P12: 1214.1 | Q12: 1259.29 | R12: 356.56 | S12: 366.08 | T12: 380.18 | U12: 234.34 | V12: 229.93 | W12: 236.37 | X12: =IFERROR((Q12/O12)^(1/2)-1,"N/A") -> 0.07199625 | Y12: =IFERROR((T12/R12)^(1/2)-1,"N/A") -> 0.03259097 | Z12: =R12/O12 -> 0.32538191 | AA12: =S12/P12 -> 0.30152376 | AB12: =T12/Q12 -> 0.30190028
B13: Pegasus Hava Tasimaciligi Anonim Sirketi | C13: IBSE:PGSUS | D13: 8.69 | E13: 102.3 | F13: =D13*E13 -> 888.987 | G13: 1.69 | H13: 0.2 | I13: -488.6 | J13: =2325.1-K13 -> 445.98496 | K13: =(33012.1+6136.13)*0.048 -> 1879.115 | L13: 0 | M13: 0 | N13: =F13+I13+J13+K13+L13+M13 -> 2725.487 | O13: 1628.17 | P13: 2412.22 | Q13: 2915.87 | R13: 456.19 | S13: 755.68 | T13: 1038.98 | U13: 48.29 | V13: 154.96 | W13: 490.11 | X13: =IFERROR((Q13/O13)^(1/2)-1,"N/A") -> 0.33824061 | Y13: =IFERROR((T13/R13)^(1/2)-1,"N/A") -> 0.50914411 | Z13: =R13/O13 -> 0.28018573 | AA13: =S13/P13 -> 0.31327159 | AB13: =T13/Q13 -> 0.35631904
B14: Norwegian Air Shuttle ASA | C14: OB:NAS | D14: 0.84 | E14: 930 | F14: =D14*E14 -> 781.2 | G14: 0.99 | H14: 0.22 | I14: -649.5 | J14: =884.8-K14 -> 360.7504 | K14: =(1103.3+4990.3)*0.086 -> 524.0496 | L14: 0 | M14: 0 | N14: =F14+I14+J14+K14+L14+M14 -> 1016.5 | O14: 1558.63 | P14: 2070.58 | Q14: 2295.52 | R14: -23.16 | S14: 282.04 | T14: 416.77 | U14: 15.01 | V14: 42.59 | W14: 96.54 | X14: =IFERROR((Q14/O14)^(1/2)-1,"N/A") -> 0.21358172 | Y14: =IFERROR((T14/R14)^(1/2)-1,"N/A") -> N/A | Z14: =R14/O14 -> -0.014859203 | AA14: =S14/P14 -> 0.13621304 | AB14: =T14/Q14 -> 0.18155799
B15: Jazeera Airways K.S.C.P. | C15: KWSE:JAZEERA | D15: 5.47 | E15: 220 | F15: =D15*E15 -> 1203.4 | G15: 0.85 | H15: 0.15 | I15: -124.3 | J15: =460.4-K15 -> 60.3684 | K15: =(21.27+121.09)*2.81 -> 400.0316 | L15: 0 | M15: 0 | N15: =F15+I15+J15+K15+L15+M15 -> 1539.5 | O15: 401.18 | P15: 484.55 | Q15: 538.03 | R15: 116.15 | S15: 144.55 | T15: 181.01 | U15: 44.89 | V15: 66.34 | W15: 77.71 | X15: =IFERROR((Q15/O15)^(1/2)-1,"N/A") -> 0.15806679 | Y15: =IFERROR((T15/R15)^(1/2)-1,"N/A") -> 0.24836527 | Z15: =R15/O15 -> 0.28952091 | AA15: =S15/P15 -> 0.29831803 | AB15: =T15/Q15 -> 0.33643105
B17: Maximum | D17: =MAX(D9:D15) -> 25.32 | F17: =MAX(F9:F15) -> 12929.928 | G17: =MAX(G9:G15) -> 2.21 | N17: =MAX(N9:N15) -> 13295.728 | O17: =MAX(O9:O15) -> 7564.455 | P17: =MAX(P9:P15) -> 10051.66 | Q17: =MAX(Q9:Q15) -> 11420.625 | R17: =MAX(R9:R15) -> 1523.08 | S17: =MAX(S9:S15) -> 2036.42 | T17: =MAX(T9:T15) -> 2520.765 | U17: =MAX(U9:U15) -> 745.09 | ... AB17: =MAX(AB9:AB15) -> 0.35631904
B18: 75th Percentile | D18: =QUARTILE(D9:D15,3) -> 10.586 | F18: =QUARTILE(F9:F15,3) -> 2543.1875 | G18: =QUARTILE(G9:G15,3) -> 1.815 | N18: =QUARTILE(N9:N15,3) -> 3851.6055 | O18: =QUARTILE(O9:O15,3) -> 3375.5487 | P18: =QUARTILE(P9:P15,3) -> 4685.4263 | Q18: =QUARTILE(Q9:Q15,3) -> 5435.6388 | R18: =QUARTILE(R9:R15,3) -> 406.375 | S18: =QUARTILE(S9:S15,3) -> 743.7075 | T18: =QUARTILE(T9:T15,3) -> 1096.5725 | U18: =QUARTILE(U9:U15,3) -> 163.2375 | ... AB18: =QUARTILE(AB9:AB15,3) -> 0.31916567
B19: Median | D19: =MEDIAN(D9:D15) -> 8.69 | F19: =MEDIAN(F9:F15) -> 2100.1954 | G19: =MEDIAN(G9:G15) -> 1.48 | N19: =MEDIAN(N9:N15) -> 2151.351 | O19: =MEDIAN(O9:O15) -> 1628.17 | P19: =MEDIAN(P9:P15) -> 2412.22 | Q19: =MEDIAN(Q9:Q15) -> 2915.87 | R19: =MEDIAN(R9:R15) -> 347.325 | S19: =MEDIAN(S9:S15) -> 552.4775 | T19: =MEDIAN(T9:T15) -> 612.495 | U19: =MEDIAN(U9:U15) -> 48.29 | ... AB19: =MEDIAN(AB9:AB15) -> 0.22072041
B20: 25th Percentile | D20: =QUARTILE(D9:D15,1) -> 3.155 | F20: =QUARTILE(F9:F15,1) -> 1046.1935 | G20: =QUARTILE(G9:G15,1) -> 0.92 | N20: =QUARTILE(N9:N15,1) -> 1490.6977 | O20: =QUARTILE(O9:O15,1) -> 1327.225 | P20: =QUARTILE(P9:P15,1) -> 1642.34 | Q20: =QUARTILE(Q9:Q15,1) -> 1777.405 | R20: =QUARTILE(R9:R15,1) -> 113.905 | S20: =QUARTILE(S9:S15,1) -> 324.06 | T20: =QUARTILE(T9:T15,1) -> 398.475 | U20: =QUARTILE(U9:U15,1) -> 29.95 | ... AB20: =QUARTILE(AB9:AB15,1) -> 0.19858715
B21: Minimum | D21: =MIN(D9:D15) -> 0.53 | F21: =MIN(F9:F15) -> 781.2 | G21: =MIN(G9:G15) -> 0.67 | N21: =MIN(N9:N15) -> 1016.5 | O21: =MIN(O9:O15) -> 401.18 | P21: =MIN(P9:P15) -> 484.55 | Q21: =MIN(Q9:Q15) -> 538.03 | R21: =MIN(R9:R15) -> -23.16 | S21: =MIN(S9:S15) -> 144.55 | T21: =MIN(T9:T15) -> 181.01 | U21: =MIN(U9:U15) -> -508.165 | ... AB21: =MIN(AB9:AB15) -> 0.11099116
B23: =Company_Name -> easyJet plc | C23: =Ticker -> LSE:EZJ | D23: =Share_Price -> 4.531 | E23: =Diluted_Shares -> 759 | F23: =D23*E23 -> 3439.029 | G23: 2.45 | H23: =Tax_Rate -> 0.25 | I23: =DCF!E20 -> -3505 | J23: =DCF!E22 -> 3046 | K23: =DCF!E24 -> 1055 | L23: =DCF!E23 -> 0 | M23: =DCF!E21+SUM(DCF!E25:E26) -> -608.94246 | N23: =F23+I23+J23+K23+L23+M23 -> 3426.0865 | O23: =EZJ!K94*0.5+EZJ!L94+EZJ!M94*0.5 -> 4538.6712 | P23: =EZJ!M94*0.5+EZJ!N94+EZJ!O94*0.5 -> 6310.6335 | Q23: =EZJ!N94*0.5+EZJ!O94+EZJ!P94*0.5 -> 6940.9992 | R23: =EZJ!K97*0.5+EZJ!L97+EZJ!M97*0.5 -> 314.60379 | S23: =EZJ!M97*0.5+EZJ!N97+EZJ!O97*0.5 -> 715.0827 | T23: =EZJ!N97*0.5+EZJ!O97+EZJ!P97*0.5 -> 853.71559 | U23: =EZJ!K114+EZJ!L114*0.5+EZJ!M114*0.5 -> -504.72648 | V23: =EZJ!M114*0.5+EZJ!N114+EZJ!O114*0.5 -> 111.90475 | W23: =EZJ!N114*0.5+EZJ!O114+EZJ!P114*0.5 -> 199.9336 | X23: =IFERROR((Q23/O23)^(1/2)-1,"N/A") -> 0.23664954 | Y23: =IFERROR((T23/R23)^(1/2)-1,"N/A") -> 0.64730732 | Z23: =R23/O23 -> 0.069316278 | AA23: =S23/P23 -> 0.11331393
B25: Valuation Statistics: | F25: Capitalisation | O25: Enterprise Value / | R25: Enterprise Value /
F26: Equity | N26: Enterprise | O26: Revenue | R26: EBITDA | U26: P / E Multiple
B27: Company Name | F27: Value | N27: Value | O27: =$O$8 -> CY 22 | P27: =$P$8 -> CY 23 | Q27: =$Q$8 -> CY 24 | R27: =$O$8 -> CY 22 | S27: =$P$8 -> CY 23 | T27: =$Q$8 -> CY 24 | U27: =$O$8 -> CY 22 | V27: =$P$8 -> CY 23 | W27: =$Q$8 -> CY 24
B28: =B9 -> Ryanair Holdings plc | C28: =C9 -> ISE:RYA | F28: =F9 -> 12929.928 | N28: =N9 -> 13295.728 | O28: =IFERROR(IF(OR(+$N9/O9<0,+$N9/O9>=100),"NM",+$N9/O9),"N/A") -> 1.7576584 | P28: =IFERROR(IF(OR(+$N9/P9<0,+$N9/P9>=100),"NM",+$N9/P9),"N/A") -> 1.3227395 | Q28: =IFERROR(IF(OR(+$N9/Q9<0,+$N9/Q9>=100),"NM",+$N9/Q9),"N/A") -> 1.1641857 | R28: =IFERROR(IF(OR(+$N9/R9<0,+$N9/R9>=100),"NM",+$N9/R9),"N/A") -> 8.7295007 | S28: =IFERROR(IF(OR(+$N9/S9<0,+$N9/S9>=100),"NM",+$N9/S9),"N/A") -> 6.5289714 | T28: =IFERROR(IF(OR(+$N9/T9<0,+$N9/T9>=100),"NM",+$N9/T9),"N/A") -> 5.2744814 | U28: =IFERROR(IF(OR(+$F9/U9<0,+$F9/U9>=100),"NM",+$F9/U9),"N/A") -> 17.353512 | V28: =IFERROR(IF(OR(+$F9/V9<0,+$F9/V9>=100),"NM",+$F9/V9),"N/A") -> 11.603451 | W28: =IFERROR(IF(OR(+$F9/W9<0,+$F9/W9>=100),"NM",+$F9/W9),"N/A") -> 8.8386194
B29: =B10 -> Wizz Air Holdings Plc | C29: =C10 -> LSE:WIZZ | F29: =F10 -> 2613.024 | N29: =N10 -> 4977.724 | O29: =IFERROR(IF(OR(+$N10/O10<0,+$N10/O10>=100),"NM",+$N10/O10),"N/A") -> 1.71011 | P29: =IFERROR(IF(OR(+$N10/P10<0,+$N10/P10>=100),"NM",+$N10/P10),"N/A") -> 1.1623855 | Q29: =IFERROR(IF(OR(+$N10/Q10<0,+$N10/Q10>=100),"NM",+$N10/Q10),"N/A") -> 0.92991772 | R29: =IFERROR(IF(OR(+$N10/R10<0,+$N10/R10>=100),"NM",+$N10/R10),"N/A") -> 44.579294 | S29: =IFERROR(IF(OR(+$N10/S10<0,+$N10/S10>=100),"NM",+$N10/S10),"N/A") -> 6.8026321 | T29: =IFERROR(IF(OR(+$N10/T10<0,+$N10/T10>=100),"NM",+$N10/T10),"N/A") -> 4.3128357 | U29: =IFERROR(IF(OR(+$F10/U10<0,+$F10/U10>=100),"NM",+$F10/U10),"N/A") -> NM | V29: =IFERROR(IF(OR(+$F10/V10<0,+$F10/V10>=100),"NM",+$F10/V10),"N/A") -> 51.286045 | W29: =IFERROR(IF(OR(+$F10/W10<0,+$F10/W10>=100),"NM",+$F10/W10),"N/A") -> 6.2003381
B30: =B11 -> Jet2 plc | C30: =C11 -> AIM:JET2 | F30: =F11 -> 2100.1954 | N30: =N11 -> 1441.8954 | O30: =IFERROR(IF(OR(+$N11/O11<0,+$N11/O11>=100),"NM",+$N11/O11),"N/A") -> 0.37546084 | P30: =IFERROR(IF(OR(+$N11/P11<0,+$N11/P11>=100),"NM",+$N11/P11),"N/A") -> 0.28336257 | Q30: =IFERROR(IF(OR(+$N11/Q11<0,+$N11/Q11>=100),"NM",+$N11/Q11),"N/A") -> 0.26128808 | R30: =IFERROR(IF(OR(+$N11/R11<0,+$N11/R11>=100),"NM",+$N11/R11),"N/A") -> 4.1514299 | S30: =IFERROR(IF(OR(+$N11/S11<0,+$N11/S11>=100),"NM",+$N11/S11),"N/A") -> 2.6098717 | T30: =IFERROR(IF(OR(+$N11/T11<0,+$N11/T11>=100),"NM",+$N11/T11),"N/A") -> 2.3541342 | U30: =IFERROR(IF(OR(+$F11/U11<0,+$F11/U11>=100),"NM",+$F11/U11),"N/A") -> 22.794762 | V30: =IFERROR(IF(OR(+$F11/V11<0,+$F11/V11>=100),"NM",+$F11/V11),"N/A") -> 9.137641 | W30: =IFERROR(IF(OR(+$F11/W11<0,+$F11/W11>=100),"NM",+$F11/W11),"N/A") -> 7.8456252
B31: =B12 -> Air Arabia PJSC | C31: =C12 -> DFM:AIRARABIA | F31: =F12 -> 2473.351 | N31: =N12 -> 2151.351 | O31: =IFERROR(IF(OR(+$N12/O12<0,+$N12/O12>=100),"NM",+$N12/O12),"N/A") -> 1.9632339 | P31: =IFERROR(IF(OR(+$N12/P12<0,+$N12/P12>=100),"NM",+$N12/P12),"N/A") -> 1.7719718 | Q31: =IFERROR(IF(OR(+$N12/Q12<0,+$N12/Q12>=100),"NM",+$N12/Q12),"N/A") -> 1.7083841 | R31: =IFERROR(IF(OR(+$N12/R12<0,+$N12/R12>=100),"NM",+$N12/R12),"N/A") -> 6.0336297 | S31: =IFERROR(IF(OR(+$N12/S12<0,+$N12/S12>=100),"NM",+$N12/S12),"N/A") -> 5.8767237 | T31: =IFERROR(IF(OR(+$N12/T12<0,+$N12/T12>=100),"NM",+$N12/T12),"N/A") -> 5.6587695 | U31: =IFERROR(IF(OR(+$F12/U12<0,+$F12/U12>=100),"NM",+$F12/U12),"N/A") -> 10.55454 | V31: =IFERROR(IF(OR(+$F12/V12<0,+$F12/V12>=100),"NM",+$F12/V12),"N/A") -> 10.756974 | W31: =IFERROR(IF(OR(+$F12/W12<0,+$F12/W12>=100),"NM",+$F12/W12),"N/A") -> 10.463896
B32: =B13 -> Pegasus Hava Tasimaciligi Anonim Sirketi | C32: =C13 -> IBSE:PGSUS | F32: =F13 -> 888.987 | N32: =N13 -> 2725.487 | O32: =IFERROR(IF(OR(+$N13/O13<0,+$N13/O13>=100),"NM",+$N13/O13),"N/A") -> 1.6739573 | P32: =IFERROR(IF(OR(+$N13/P13<0,+$N13/P13>=100),"NM",+$N13/P13),"N/A") -> 1.1298667 | Q32: =IFERROR(IF(OR(+$N13/Q13<0,+$N13/Q13>=100),"NM",+$N13/Q13),"N/A") -> 0.93470799 | R32: =IFERROR(IF(OR(+$N13/R13<0,+$N13/R13>=100),"NM",+$N13/R13),"N/A") -> 5.9744558 | S32: =IFERROR(IF(OR(+$N13/S13<0,+$N13/S13>=100),"NM",+$N13/S13),"N/A") -> 3.6066682 | T32: =IFERROR(IF(OR(+$N13/T13<0,+$N13/T13>=100),"NM",+$N13/T13),"N/A") -> 2.6232334 | U32: =IFERROR(IF(OR(+$F13/U13<0,+$F13/U13>=100),"NM",+$F13/U13),"N/A") -> 18.409339 | V32: =IFERROR(IF(OR(+$F13/V13<0,+$F13/V13>=100),"NM",+$F13/V13),"N/A") -> 5.7368805 | W32: =IFERROR(IF(OR(+$F13/W13<0,+$F13/W13>=100),"NM",+$F13/W13),"N/A") -> 1.813852
B33: =B14 -> Norwegian Air Shuttle ASA | C33: =C14 -> OB:NAS | F33: =F14 -> 781.2 | N33: =N14 -> 1016.5 | O33: =IFERROR(IF(OR(+$N14/O14<0,+$N14/O14>=100),"NM",+$N14/O14),"N/A") -> 0.65217531 | P33: =IFERROR(IF(OR(+$N14/P14<0,+$N14/P14>=100),"NM",+$N14/P14),"N/A") -> 0.49092525 | Q33: =IFERROR(IF(OR(+$N14/Q14<0,+$N14/Q14>=100),"NM",+$N14/Q14),"N/A") -> 0.44281906 | R33: =IFERROR(IF(OR(+$N14/R14<0,+$N14/R14>=100),"NM",+$N14/R14),"N/A") -> NM | S33: =IFERROR(IF(OR(+$N14/S14<0,+$N14/S14>=100),"NM",+$N14/S14),"N/A") -> 3.6040987 | T33: =IFERROR(IF(OR(+$N14/T14<0,+$N14/T14>=100),"NM",+$N14/T14),"N/A") -> 2.4389951 | U33: =IFERROR(IF(OR(+$F14/U14<0,+$F14/U14>=100),"NM",+$F14/U14),"N/A") -> 52.045303 | V33: =IFERROR(IF(OR(+$F14/V14<0,+$F14/V14>=100),"NM",+$F14/V14),"N/A") -> 18.342334 | W33: =IFERROR(IF(OR(+$F14/W14<0,+$F14/W14>=100),"NM",+$F14/W14),"N/A") -> 8.0919826
B34: =B15 -> Jazeera Airways K.S.C.P. | C34: =C15 -> KWSE:JAZEERA | F34: =F15 -> 1203.4 | N34: =N15 -> 1539.5 | O34: =IFERROR(IF(OR(+$N15/O15<0,+$N15/O15>=100),"NM",+$N15/O15),"N/A") -> 3.8374296 | P34: =IFERROR(IF(OR(+$N15/P15<0,+$N15/P15>=100),"NM",+$N15/P15),"N/A") -> 3.1771747 | Q34: =IFERROR(IF(OR(+$N15/Q15<0,+$N15/Q15>=100),"NM",+$N15/Q15),"N/A") -> 2.8613646 | R34: =IFERROR(IF(OR(+$N15/R15<0,+$N15/R15>=100),"NM",+$N15/R15),"N/A") -> 13.254412 | S34: =IFERROR(IF(OR(+$N15/S15<0,+$N15/S15>=100),"NM",+$N15/S15),"N/A") -> 10.650294 | T34: =IFERROR(IF(OR(+$N15/T15<0,+$N15/T15>=100),"NM",+$N15/T15),"N/A") -> 8.505055 | U34: =IFERROR(IF(OR(+$F15/U15<0,+$F15/U15>=100),"NM",+$F15/U15),"N/A") -> 26.807752 | V34: =IFERROR(IF(OR(+$F15/V15<0,+$F15/V15>=100),"NM",+$F15/V15),"N/A") -> 18.139885 | W34: =IFERROR(IF(OR(+$F15/W15<0,+$F15/W15>=100),"NM",+$F15/W15),"N/A") -> 15.48578
B36: Maximum | F36: =MAX(F28:F34) -> 12929.928 | N36: =MAX(N28:N34) -> 13295.728 | O36: =MAX(O28:O34) -> 3.8374296 | P36: =MAX(P28:P34) -> 3.1771747 | Q36: =MAX(Q28:Q34) -> 2.8613646 | R36: =MAX(R28:R34) -> 44.579294 | S36: =MAX(S28:S34) -> 10.650294 | T36: =MAX(T28:T34) -> 8.505055 | U36: =MAX(U28:U34) -> 52.045303 | ... W36: =MAX(W28:W34) -> 15.48578
B37: 75th Percentile | F37: =QUARTILE(F28:F34,3) -> 2543.1875 | N37: =QUARTILE(N28:N34,3) -> 3851.6055 | O37: =QUARTILE(O28:O34,3) -> 1.8604462 | P37: =QUARTILE(P28:P34,3) -> 1.5473557 | Q37: =QUARTILE(Q28:Q34,3) -> 1.4362849 | R37: =QUARTILE(R28:R34,3) -> 12.123184 | S37: =QUARTILE(S28:S34,3) -> 6.6658018 | T37: =QUARTILE(T28:T34,3) -> 5.4666254 | U37: =QUARTILE(U28:U34,3) -> 25.804505 | ... W37: =QUARTILE(W28:W34,3) -> 9.6512575
B38: Median | F38: =MEDIAN(F28:F34) -> 2100.1954 | N38: =MEDIAN(N28:N34) -> 2151.351 | O38: =MEDIAN(O28:O34) -> 1.71011 | P38: =MEDIAN(P28:P34) -> 1.1623855 | Q38: =MEDIAN(Q28:Q34) -> 0.93470799 | R38: =MEDIAN(R28:R34) -> 7.3815652 | S38: =MEDIAN(S28:S34) -> 5.8767237 | T38: =MEDIAN(T28:T34) -> 4.3128357 | U38: =MEDIAN(U28:U34) -> 20.602051 | ... W38: =MEDIAN(W28:W34) -> 8.0919826
B39: 25th Percentile | F39: =QUARTILE(F28:F34,1) -> 1046.1935 | N39: =QUARTILE(N28:N34,1) -> 1490.6977 | O39: =QUARTILE(O28:O34,1) -> 1.1630663 | P39: =QUARTILE(P28:P34,1) -> 0.81039596 | Q39: =QUARTILE(Q28:Q34,1) -> 0.68636839 | R39: =QUARTILE(R28:R34,1) -> 5.9892493 | S39: =QUARTILE(S28:S34,1) -> 3.6053834 | T39: =QUARTILE(T28:T34,1) -> 2.5311142 | U39: =QUARTILE(U28:U34,1) -> 17.617469 | ... W39: =QUARTILE(W28:W34,1) -> 7.0229816
B40: Minimum | F40: =MIN(F28:F34) -> 781.2 | N40: =MIN(N28:N34) -> 1016.5 | O40: =MIN(O28:O34) -> 0.37546084 | P40: =MIN(P28:P34) -> 0.28336257 | Q40: =MIN(Q28:Q34) -> 0.26128808 | R40: =MIN(R28:R34) -> 4.1514299 | S40: =MIN(S28:S34) -> 2.6098717 | T40: =MIN(T28:T34) -> 2.3541342 | U40: =MIN(U28:U34) -> 10.55454 | ... W40: =MIN(W28:W34) -> 1.813852
B42: =Company_Name -> easyJet plc | C42: =Ticker -> LSE:EZJ | F42: =F23 -> 3439.029 | N42: =N23 -> 3426.0865 | O42: =IFERROR(IF(OR(+$N23/O23<0,+$N23/O23>=100),"NM",+$N23/O23),"N/A") -> 0.75486556 | P42: =IFERROR(IF(OR(+$N23/P23<0,+$N23/P23>=100),"NM",+$N23/P23),"N/A") -> 0.54290691 | Q42: =IFERROR(IF(OR(+$N23/Q23<0,+$N23/Q23>=100),"NM",+$N23/Q23),"N/A") -> 0.49360134 | R42: =IFERROR(IF(OR(+$N23/R23<0,+$N23/R23>=100),"NM",+$N23/R23),"N/A") -> 10.890163 | S42: =IFERROR(IF(OR(+$N23/S23<0,+$N23/S23>=100),"NM",+$N23/S23),"N/A") -> 4.7911753 | T42: =IFERROR(IF(OR(+$N23/T23<0,+$N23/T23>=100),"NM",+$N23/T23),"N/A") -> 4.0131475 | U42: =IFERROR(IF(OR(+$F23/U23<0,+$F23/U23>=100),"NM",+$F23/U23),"N/A") -> NM | V42: =IFERROR(IF(OR(+$F23/V23<0,+$F23/V23>=100),"NM",+$F23/V23),"N/A") -> 30.731753 | W42: =IFERROR(IF(OR(+$F23/W23<0,+$F23/W23>=100),"NM",+$F23/W23),"N/A") -> 17.200856

Sheet MA_Comps
B2: Precedent Transactions - EMEA Airline Sellers with Transaction Enterprise Values Above £500 Million
B3: Announced Between January 1st, 2002, and August 15th, 2024
B4: =Public_Comps!$B$3 -> (£ GBP in Millions Except Per Share Amounts in GBP as Stated)
B5: (Only >= 50% Acquisitions; Asset Sales and Divestitures Also Included)
B7: =Company_Name&" - Comparable M&A Transactions:" -> easyJet plc - Comparable M&A Transactions: | I7: Valuation Multiples
F8: Transaction | I8: TEV / | J8: TEV /
D9: Announcement | E9: Percentage | F9: Enterprise | G9: NTM | H9: NTM | I9: NTM | J9: NTM
B10: Acquirer Name | C10: Target Name | D10: Date | E10: Acquired | F10: Value | G10: Revenue | H10: EBITDA | I10: Revenue | J10: EBITDA
B11: Air France SA (nka:Air France-KLM SA (ENXTPA:AF)) | C11: KLM Royal Dutch Airlines (OTCPK:KLMR) | D11: 37894 | E11: 1 | F11: 3021.44 | G11: 4316.3429 | H11: 348.49366 | I11: =IFERROR(IF(OR(+$F11/G11<0,+$F11/G11>=100),"NM",+$F11/G11),"N/A") -> 0.7 | J11: =IFERROR(IF(OR(+$F11/H11<0,+$F11/H11>=100),"NM",+$F11/H11),"N/A") -> 8.67
B12: British Airways Plc | C12: IBERIA LAE SA | D12: 40129 | E12: 0.8685 | F12: 763.25 | G12: 4240.2778 | H12: 30.714286 | I12: =IFERROR(IF(OR(+$F12/G12<0,+$F12/G12>=100),"NM",+$F12/G12),"N/A") -> 0.18 | J12: =IFERROR(IF(OR(+$F12/H12<0,+$F12/H12>=100),"NM",+$F12/H12),"N/A") -> 24.85
B13: International Consolidated Airlines Group S.A. (LSE:IAG) | C13: Aer Lingus Group DAC | D13: 41991 | E13: 1 | F13: 869.58 | G13: 1175.1081 | H13: 131.75455 | I13: =IFERROR(IF(OR(+$F13/G13<0,+$F13/G13>=100),"NM",+$F13/G13),"N/A") -> 0.74 | J13: =IFERROR(IF(OR(+$F13/H13<0,+$F13/H13>=100),"NM",+$F13/H13),"N/A") -> 6.6
B14: Deutsche Lufthansa AG (XTRA:LHA) | C14: Austrian Airlines AG | D14: 39871 | E14: 0.584 | F14: 1162.4 | G14: 2152.5926 | H14: 212.11679 | I14: =IFERROR(IF(OR(+$F14/G14<0,+$F14/G14>=100),"NM",+$F14/G14),"N/A") -> 0.54 | J14: =IFERROR(IF(OR(+$F14/H14<0,+$F14/H14>=100),"NM",+$F14/H14),"N/A") -> 5.48
B15: Deutsche Lufthansa AG (XTRA:LHA) | C15: Swiss International Air Lines AG | D15: 38433 | E15: 0.846 | F15: =(319/49%-493.3+71.2+177+145.4+699.7+11.2)*0.87 -> 1098.1318 | G15: 3273.9 | H15: 312.9 | I15: =IFERROR(IF(OR(+$F15/G15<0,+$F15/G15>=100),"NM",+$F15/G15),"N/A") -> 0.33542007 | J15: =IFERROR(IF(OR(+$F15/H15<0,+$F15/H15>=100),"NM",+$F15/H15),"N/A") -> 3.5095294
B16: DGN Corporation; Hpgb, SGPS S.A | C16: TAP - Transportes Aéreos Portugueses, SGPS, S.A. | D16: 42166 | E16: 0.61 | F16: 687.41 | G16: 2088.2 | H16: 57.6 | I16: =IFERROR(IF(OR(+$F16/G16<0,+$F16/G16>=100),"NM",+$F16/G16),"N/A") -> 0.32918782 | J16: =IFERROR(IF(OR(+$F16/H16<0,+$F16/H16>=100),"NM",+$F16/H16),"N/A") -> 11.934201
B17: Blue-Sky Transport Holding ; Langflug ehf ; Naust ehf | C17: Icelandair Group hf. (ICSE:ICEAIR) | D17: 39006 | E17: 0.505 | F17: 744.51 | G17: 385.5 | H17: 33.3 | I17: =IFERROR(IF(OR(+$F17/G17<0,+$F17/G17>=100),"NM",+$F17/G17),"N/A") -> 1.931284 | J17: =IFERROR(IF(OR(+$F17/H17<0,+$F17/H17>=100),"NM",+$F17/H17),"N/A") -> 22.357658
C19: Maximum | F19: =MAX(F11:F17) -> 3021.44 | G19: =MAX(G11:G17) -> 4316.3429 | H19: =MAX(H11:H17) -> 348.49366 | I19: =MAX(I11:I17) -> 1.931284 | J19: =MAX(J11:J17) -> 24.85
C20: 75th Percentile | F20: =QUARTILE(F11:F17,3) -> 1130.2659 | G20: =QUARTILE(G11:G17,3) -> 3757.0889 | H20: =QUARTILE(H11:H17,3) -> 262.50839 | I20: =QUARTILE(I11:I17,3) -> 0.72 | J20: =QUARTILE(J11:J17,3) -> 17.14593
C21: Median | F21: =MEDIAN(F11:F17) -> 869.58 | G21: =MEDIAN(G11:G17) -> 2152.5926 | H21: =MEDIAN(H11:H17) -> 131.75455 | I21: =MEDIAN(I11:I17) -> 0.54 | J21: =MEDIAN(J11:J17) -> 8.67
C22: 25th Percentile | F22: =QUARTILE(F11:F17,1) -> 753.88 | G22: =QUARTILE(G11:G17,1) -> 1631.6541 | H22: =QUARTILE(H11:H17,1) -> 45.45 | I22: =QUARTILE(I11:I17,1) -> 0.33230394 | J22: =QUARTILE(J11:J17,1) -> 6.04
